Workbook

Sheet Cover
B2: SAMA Capital Adequacy Return — Q17
B3: CAR-SA-01 | Quarterly Prudential Return
B5: Bank Full Legal Name
B6: SAMA License Number
B7: Reporting Quarter | C7: e.g. Q2 2025
B8: Reporting Period End Date | C8: DD/MM/YYYY
B9: Submission Date | C9: DD/MM/YYYY
B10: Prepared By (Name)
B11: Reviewed By (Name)
B12: Approved By (Board / CEO)
B13: Reporting Currency | C13: SAR
B14: Units | C14: SAR '000
B16: Declaration
B17: We confirm that the information contained in this Capital Adequacy Return is accurate and complete to the best of our knowledge and belief, and has been prepared in accordance with SAMA's Basel III Capital Adequacy Framework and all applicable SAMA circulars and guidelines.
B20: Authorised Signatory
B21: Designation
B22: Date

Sheet Summary
A1: CAR-SA-01 — Summary: Capital Adequacy Ratios
A2: All figures in SAR '000 unless otherwise stated
B4: Bank Name:
B6: Metric | C6: Amount (SAR '000) | D6: RWA (SAR '000) | E6: Ratio (%) | F6: SAMA Minimum
B7: Common Equity Tier 1 (CET1) Capital | C7: ='Schedule 1'!E11 | D7: ='Schedule 2'!E55+'Schedule 3'!E24+'Schedule 4'!E15 -> 0 | E7: =IF(D7<>0,C7/D7,"-") -> - | F7: 7.00%
B8: Additional Tier 1 (AT1) Capital | C8: ='Schedule 1'!E18 | D8: — | E8: — | F8: —
B9: Tier 1 Capital (CET1 + AT1) | C9: ='Schedule 1'!E21 | D9: — | E9: =IF($D$12<>0,C9/$D$12,"-") -> - | F9: 8.50%
B10: Tier 2 Capital | C10: ='Schedule 1'!E29 | D10: — | E10: — | F10: —
B11: Total Regulatory Capital (T1 + T2) | C11: ='Schedule 1'!E32 -> 0 | D11: — | E11: =IF($D$12<>0,C11/$D$12,"-") -> - | F11: 10.50%
B12: Total Risk-Weighted Assets (RWA) | C12: — | D12: ='Schedule 2'!E55+'Schedule 3'!E24+'Schedule 4'!E15 -> 0 | E12: — | F12: —
B14: Capital Buffers
B15: Buffer | C15: Required (%) | D15: Held (%) | E15: Surplus / (Deficit) | F15: Status
B16: Capital Conservation Buffer (CCB) | C16: 2.50% | E16: =D16-C16 -> -0.025 | F16: =IF(D16>=C16,"✓ Compliant","✗ Breach") -> ✗ Breach
B17: Countercyclical Capital Buffer (CCyB) | C17: 0.00% | E17: =D17-C17 -> 0 | F17: =IF(D17>=C17,"✓ Compliant","✗ Breach") -> ✗ Breach
B18: D-SIB Surcharge (if applicable) | C18: 1.00% | E18: =D18-C18 -> -0.01 | F18: =IF(D18>=C18,"✓ Compliant","✗ Breach") -> ✗ Breach
B19: Total Combined Buffer Requirement | C19: =C16+C17+C18 -> 0.035
A22: Color legend: Blue = Input (hardcoded) | Black = Formula | Green = Cross-sheet link | Yellow bg = Key assumption

Sheet Schedule 1
A1: Schedule 1 — Regulatory Capital Composition
A2: All figures in SAR '000
A4: Color legend: Blue = Input (hardcoded) | Black = Formula | Green = Cross-sheet link | Yellow bg = Key assumption
B5: Line Item | C5: Gross Amount (SAR '000) | D5: Regulatory Adjustments | E5: Net Regulatory Capital (SAR '000)
B6: PART A — Common Equity Tier 1 (CET1) Capital
B7: Paid-up ordinary share capital / common shares | E7: =IF(C7="","",C7)
B8: Share premium (relating to CET1) | E8: =IF(C8="","",C8)
B9: Retained earnings (prior year) | E9: =IF(C9="","",C9)
B10: Current year profit attributable to shareholders (net of dividends) | E10: =IF(C10="","",C10)
B11: Accumulated Other Comprehensive Income (AOCI) | E11: =IF(C11="","",C11)
B12: Other disclosed reserves | E12: =IF(C12="","",C12)
B13: Minority interest — eligible amount | E13: =IF(C13="","",C13)
B14: Sub-total: CET1 before regulatory adjustments | C14: =SUM(C7:C13) -> 0 | E14: =C14 -> 0
B15: Regulatory Deductions from CET1
B16: Goodwill (net of associated deferred tax liability) | E16: =IF(C16="","",C16)
B17: Other intangible assets (net of associated deferred tax liability) | E17: =IF(C17="","",C17)
B18: Deferred tax assets that rely on future profitability (excluding those from temporary differences) | E18: =IF(C18="","",C18)
B19: Cash flow hedge reserve | E19: =IF(C19="","",C19)
B20: Shortfall of provisions to expected losses (IRB banks only) | E20: =IF(C20="","",C20)
B21: Securitisation gain on sale | E21: =IF(C21="","",C21)
B22: Gains/losses due to changes in own credit risk on fair-valued liabilities | E22: =IF(C22="","",C22)
B23: Defined benefit pension fund net assets | E23: =IF(C23="","",C23)
B24: Investments in own CET1 instruments (treasury shares) | E24: =IF(C24="","",C24)
B25: Reciprocal cross-holdings in CET1 of other financial institutions | E25: =IF(C25="","",C25)
B26: Significant investments in CET1 of unconsolidated financial institutions (>10%) | E26: =IF(C26="","",C26)
B27: Non-significant investments in CET1 of financial institutions — amounts above 10% threshold | E27: =IF(C27="","",C27)
... B31: Other deductions as prescribed by SAMA | E31: =IF(C31="","",C31)
B32: Total Regulatory Deductions from CET1 | C32: =SUM(C16:C31) -> 0 | E32: =C32 -> 0
B33: TOTAL CET1 CAPITAL (NET) | E33: =C14-C32 -> 0
B35: PART B — Additional Tier 1 (AT1) Capital
B36: Qualifying AT1 instruments (Perpetual Sukuk / bonds meeting Basel III AT1 criteria) | E36: =IF(C36="","",C36)
B37: Share premium relating to AT1 instruments | E37: =IF(C37="","",C37)
B38: Less: Investments in own AT1 instruments | E38: =IF(C38="","",C38)
B39: Less: Reciprocal cross-holdings in AT1 of other financial institutions | E39: =IF(C39="","",C39)
B40: Less: Significant investments in AT1 of unconsolidated financial institutions | E40: =IF(C40="","",C40)
B41: Other AT1 deductions as prescribed by SAMA | E41: =IF(C41="","",C41)
B42: TOTAL AT1 CAPITAL | E42: =SUM(C36:C41) -> 0
B43: TOTAL TIER 1 CAPITAL (CET1 + AT1) | E43: =E33+E42 -> 0
B45: PART C — Tier 2 Capital
B46: Qualifying Tier 2 instruments (Subordinated Sukuk / bonds — minimum 5 year maturity) | E46: =IF(C46="","",C46)
...

Sheet Schedule 2
A1: Schedule 2 — Credit Risk Risk-Weighted Assets (Standardized Approach)
A2: All figures in SAR '000
A4: Color legend: Blue = Input (hardcoded) | Black = Formula | Green = Cross-sheet link | Yellow bg = Key assumption
B5: Exposure Class | C5: On-Balance Sheet Exposure (SAR '000) | D5: CCF (%) | E5: Off-BS Equivalent (SAR '000) | F5: Risk Weight (%) | G5: Risk-Weighted Assets (SAR '000)
B6: A. On-Balance Sheet Exposures
B7: Claims on Saudi Government and SAMA | D7: — | E7: — | F7: 0 | G7: =IF(C7="",0,C7*F7) -> 0
B8: Claims on Saudi Government — foreign currency | D8: — | E8: — | F8: 0 | G8: =IF(C8="",0,C8*F8) -> 0
B9: Claims on GCC Governments (rated AAA to AA-) | D9: — | E9: — | F9: 0 | G9: =IF(C9="",0,C9*F9) -> 0
B10: Claims on GCC Governments (rated A+ to A-) | D10: — | E10: — | F10: 0.2 | G10: =IF(C10="",0,C10*F10) -> 0
B11: Claims on GCC Governments (rated BBB+ to B-) | D11: — | E11: — | F11: 0.5 | G11: =IF(C11="",0,C11*F11) -> 0
B12: Claims on GCC Governments (unrated) | D12: — | E12: — | F12: 1 | G12: =IF(C12="",0,C12*F12) -> 0
B13: Claims on other Sovereigns (rated AAA to AA-) | D13: — | E13: — | F13: 0 | G13: =IF(C13="",0,C13*F13) -> 0
B14: Claims on other Sovereigns (rated A+ to A-) | D14: — | E14: — | F14: 0.2 | G14: =IF(C14="",0,C14*F14) -> 0
B15: Claims on other Sovereigns (rated BBB+ to BB-) | D15: — | E15: — | F15: 0.5 | G15: =IF(C15="",0,C15*F15) -> 0
B16: Claims on other Sovereigns (below BB- / unrated) | D16: — | E16: — | F16: 1 | G16: =IF(C16="",0,C16*F16) -> 0
B17: Claims on Public Sector Entities (PSEs) — domestic | D17: — | E17: — | F17: 0.2 | G17: =IF(C17="",0,C17*F17) -> 0
B18: Claims on Public Sector Entities (PSEs) — foreign | D18: — | E18: — | F18: 0.5 | G18: =IF(C18="",0,C18*F18) -> 0
... B42: Other assets | D42: — | E42: — | F42: 1 | G42: =IF(C42="",0,C42*F42) -> 0
B43: Sub-Total: On-Balance Sheet RWA | C43: =SUM(C7:C42) -> 0 | G43: =SUM(G7:G42) -> 0
B45: B. Off-Balance Sheet Exposures
B46: Direct credit substitutes (e.g. financial guarantees) | D46: 1 | E46: =IF(C46="",0,C46*D46) -> 0 | F46: 1 | G46: =IF(E46=0,0,E46*F46) -> 0
B47: Trade finance — documentary credits (LCs, short-term) | D47: 0.2 | E47: =IF(C47="",0,C47*D47) -> 0 | F47: 1 | G47: =IF(E47=0,0,E47*F47) -> 0
B48: Trade finance — performance bonds / bid bonds | D48: 0.5 | E48: =IF(C48="",0,C48*D48) -> 0 | F48: 1 | G48: =IF(E48=0,0,E48*F48) -> 0
B49: Commitments with original maturity > 1 year | D49: 0.5 | E49: =IF(C49="",0,C49*D49) -> 0 | F49: 1 | G49: =IF(E49=0,0,E49*F49) -> 0
B50: Commitments with original maturity ≤ 1 year (or revocable) | D50: 0.2 | E50: =IF(C50="",0,C50*D50) -> 0 | F50: 1 | G50: =IF(E50=0,0,E50*F50) -> 0
B51: Repurchase / reverse repo agreements | D51: 1 | E51: =IF(C51="",0,C51*D51) -> 0 | F51: 1 | G51: =IF(E51=0,0,E51*F51) -> 0
B52: Securities lending / borrowing | D52: 1 | E52: =IF(C52="",0,C52*D52) -> 0 | F52: 1 | G52: =IF(E52=0,0,E52*F52) -> 0
B53: Derivatives — Current Exposure Method (add-on) | D53: 0.5 | E53: =IF(C53="",0,C53*D53) -> 0 | F53: 1 | G53: =IF(E53=0,0,E53*F53) -> 0
B54: Other off-balance sheet items | D54: 1 | E54: =IF(C54="",0,C54*D54) -> 0 | F54: 1 | G54: =IF(E54=0,0,E54*F54) -> 0
B55: Sub-Total: Off-Balance Sheet RWA | C55: =SUM(C46:C54) -> 0 | E55: =SUM(E46:E54) -> 0 | G55: =SUM(G46:G54) -> 0
B57: TOTAL CREDIT RISK RWA | G57: =G43+G55 -> 0

Sheet Schedule 3
A1: Schedule 3 — Market Risk Capital Charge (Standardized Approach)
A2: All figures in SAR '000 | RWA = Capital Charge × 12.5
A4: Color legend: Blue = Input (hardcoded) | Black = Formula | Green = Cross-sheet link | Yellow bg = Key assumption
B5: Risk Sub-Type | C5: Net Position / Notional (SAR '000) | D5: Capital Charge Rate (%) | E5: Capital Charge (SAR '000)
B6: Interest Rate Risk
B7: Specific Risk — Government & qualifying bonds | D7: 0 | E7: =IF(OR(C7="",D7=""),0,C7*D7) -> 0
B8: Specific Risk — Other bonds (rated investment grade) | D8: 0.0025 | E8: =IF(OR(C8="",D8=""),0,C8*D8) -> 0
B9: Specific Risk — Other bonds (below investment grade) | D9: 0.08 | E9: =IF(OR(C9="",D9=""),0,C9*D9) -> 0
B10: General Market Risk — Duration method | E10: =IF(C10="",0,C10) -> 0
B11: Basis Risk add-on | E11: =IF(C11="",0,C11) -> 0
B12: Yield Curve Risk add-on | E12: =IF(C12="",0,C12) -> 0
B13: Equity Risk
B14: Specific Risk — Individual equity positions | D14: 0.08 | E14: =IF(OR(C14="",D14=""),0,C14*D14) -> 0
B15: General Market Risk — Net portfolio position | D15: 0.08 | E15: =IF(OR(C15="",D15=""),0,C15*D15) -> 0
B16: Foreign Exchange Risk
B17: Net open foreign exchange position (all currencies) | D17: 0.08 | E17: =IF(OR(C17="",D17=""),0,C17*D17) -> 0
B18: Gold net open position | D18: 0.08 | E18: =IF(OR(C18="",D18=""),0,C18*D18) -> 0
B19: Commodities Risk
B20: Commodities — Simplified approach | D20: 0.15 | E20: =IF(OR(C20="",D20=""),0,C20*D20) -> 0
B21: Options Risk
B22: Options — Simplified approach / Delta-plus add-on | E22: =IF(C22="",0,C22) -> 0
B23: TOTAL MARKET RISK CAPITAL CHARGE | E23: =SUM(E6:E22) -> 0
B24: MARKET RISK RWA (= Capital Charge × 12.5) | E24: =E23*12.5 -> 0

Sheet Schedule 4
A1: Schedule 4 — Operational Risk Capital Charge (Standardized Approach)
A2: All figures in SAR '000 | 3-year average Gross Income per business line
A4: Color legend: Blue = Input (hardcoded) | Black = Formula | Green = Cross-sheet link | Yellow bg = Key assumption
B5: Business Line | C5: Gross Income Year 1 (SAR '000) | D5: Gross Income Year 2 (SAR '000) | E5: Gross Income Year 3 (SAR '000) | F5: Beta Factor (%) | G5: Capital Charge (SAR '000)
B6: Corporate Finance | F6: 0.18 | G6: =IF(OR(C6="",D6="",E6=""),0,AVERAGE(C6:E6)*F6) -> 0
B7: Trading & Sales | F7: 0.18 | G7: =IF(OR(C7="",D7="",E7=""),0,AVERAGE(C7:E7)*F7) -> 0
B8: Retail Banking | F8: 0.12 | G8: =IF(OR(C8="",D8="",E8=""),0,AVERAGE(C8:E8)*F8) -> 0
B9: Commercial Banking | F9: 0.15 | G9: =IF(OR(C9="",D9="",E9=""),0,AVERAGE(C9:E9)*F9) -> 0
B10: Payment & Settlement | F10: 0.18 | G10: =IF(OR(C10="",D10="",E10=""),0,AVERAGE(C10:E10)*F10) -> 0
B11: Agency Services | F11: 0.15 | G11: =IF(OR(C11="",D11="",E11=""),0,AVERAGE(C11:E11)*F11) -> 0
B12: Asset Management | F12: 0.12 | G12: =IF(OR(C12="",D12="",E12=""),0,AVERAGE(C12:E12)*F12) -> 0
B13: Retail Brokerage | F13: 0.12 | G13: =IF(OR(C13="",D13="",E13=""),0,AVERAGE(C13:E13)*F13) -> 0
B14: TOTAL OPERATIONAL RISK CAPITAL CHARGE | C14: =SUM(C6:C13) -> 0 | D14: =SUM(D6:D13) -> 0 | E14: =SUM(E6:E13) -> 0 | G14: =SUM(G6:G13) -> 0
B15: OPERATIONAL RISK RWA (= Capital Charge × 12.5) | G15: =G14*12.5 -> 0
B18: Note: The Standardized Approach (TSA) requires SAMA's approval. Banks using the Basic Indicator Approach (BIA) apply a flat 15% beta to total gross income averaged over 3 years.

Sheet Schedule 5
A1: Schedule 5 — Capital Buffers & Combined Capital Requirement
A2: All ratios expressed as % of Total Risk-Weighted Assets
A4: Color legend: Blue = Input (hardcoded) | Black = Formula | Green = Cross-sheet link | Yellow bg = Key assumption
B5: Total RWA (reference — from Schedules 2+3+4):
B7: Buffer / Requirement | C7: Minimum Basel III (%) | D7: SAMA-Set Rate (%) | E7: Bank's Actual Ratio (%) | F7: Surplus / (Deficit) (%)
B8: Pillar 1 Minimum — CET1 | C8: 0.045 | E8: =Summary!E7 -> - | F8: =IFERROR(E8-C8,"")
B9: Pillar 1 Minimum — Tier 1 | C9: 0.06 | E9: =Summary!E9 -> - | F9: =IFERROR(E9-C9,"")
B10: Pillar 1 Minimum — Total Capital | C10: 0.08 | E10: =Summary!E11 -> - | F10: =IFERROR(E10-C10,"")
B11: Capital Conservation Buffer (CCB) | C11: 0.025 | F11: =IF(OR(E11="",C11=""),"",E11-C11)
B12: Countercyclical Capital Buffer (CCyB) | F12: =IF(OR(E12="",C12=""),"",E12-C12)
B13: D-SIB Surcharge (if designated by SAMA) | F13: =IF(OR(E13="",C13=""),"",E13-C13)
B14: Other SAMA-prescribed buffers | F14: =IF(OR(E14="",C14=""),"",E14-C14)
B15: TOTAL CET1 Requirement (incl. buffers) | E15: =Summary!E7 -> -
B16: TOTAL Tier 1 Requirement (incl. buffers) | E16: =Summary!E9 -> -
B17: TOTAL Total Capital Requirement (incl. buffers) | E17: =Summary!E11 -> -
B20: Capital Conservation Buffer — Dividend / Distribution Constraints
B21: CET1 Ratio Range (% of RWA) | C21: Minimum Capital Conservation Ratio | D21: Maximum Dividend Payout Ratio
B22: 4.5% – 5.125% (within first quartile of buffer) | C22: 100% | D22: 0%
B23: 5.125% – 5.75% (within second quartile of buffer) | C23: 80% | D23: 20%
B24: 5.75% – 6.375% (within third quartile of buffer) | C24: 60% | D24: 40%
B25: 6.375% – 7.0% (within fourth quartile of buffer) | C25: 40% | D25: 60%
B26: Above 7.0% (full buffer maintained) | C26: 0% | D26: No restriction

Sheet Schedule 6
A1: Schedule 6 — Reconciliation: Regulatory Capital to Published Financial Statements
A2: All figures in SAR '000
A4: Color legend: Blue = Input (hardcoded) | Black = Formula | Green = Cross-sheet link | Yellow bg = Key assumption
B5: Line Item | C5: Published Financial Statements (SAR '000) | D5: Regulatory Adjustments (SAR '000) | E5: Regulatory Capital Figure (SAR '000)
B6: Equity (per published balance sheet)
B7: Paid-up share capital | E7: =IF(OR(C7="",D7=""),"",C7+D7)
B8: Share premium | E8: =IF(OR(C8="",D8=""),"",C8+D8)
B9: Retained earnings | E9: =IF(OR(C9="",D9=""),"",C9+D9)
B10: Other comprehensive income / reserves | E10: =IF(OR(C10="",D10=""),"",C10+D10)
B11: Minority interests | E11: =IF(OR(C11="",D11=""),"",C11+D11)
B12: Total equity per financial statements | E12: =IF(C12="","",C12)
B13: Less: Goodwill and intangibles (net of deferred tax) | E13: =IF(OR(C13="",D13=""),"",C13+D13)
B14: Less: Deferred tax assets | E14: =IF(OR(C14="",D14=""),"",C14+D14)
B15: Less: Cash flow hedge reserve | E15: =IF(OR(C15="",D15=""),"",C15+D15)
B16: Less: Own shares (treasury stock) | E16: =IF(OR(C16="",D16=""),"",C16+D16)
B17: Less: Other regulatory deductions | E17: =IF(OR(C17="",D17=""),"",C17+D17)
B18: Plus: Eligible Tier 2 instruments | E18: =IF(OR(C18="",D18=""),"",C18+D18)
B19: Plus: General provisions (eligible amount) | E19: =IF(OR(C19="",D19=""),"",C19+D19)
B20: TOTAL REGULATORY CAPITAL (per Schedule 1) | E20: =IF(C20="","",C20)
B21: Difference (should be nil — reconciling items) | E21: =IF(E19="","",E19-'Schedule 1'!E55)
B23: PART B — RWA RECONCILIATION
B24: RWA Component | C24: Amount (SAR '000) | D24: % of Total RWA | E24: Cross-reference
B25: Credit Risk RWA | C25: ='Schedule 2'!G57 -> 0 | D25: =IF($C$28=0,"",C25/$C$28) | E25: Schedule 2
B26: Market Risk RWA | C26: ='Schedule 3'!E24 -> 0 | D26: =IF($C$28=0,"",C26/$C$28) | E26: Schedule 3
B27: Operational Risk RWA | C27: ='Schedule 4'!G15 -> 0 | D27: =IF($C$28=0,"",C27/$C$28) | E27: Schedule 4
B28: TOTAL RWA | C28: =SUM(C25:C27) -> 0 | D28: =100% -> 1
